Workbook

Sheet Dataset
A1: Question ID | D1: ID | E1: 1.Delay in delivering material to construction site | F1: 2.Monopoly of material by some suppliers | G1: 3.Prices fluctuation | H1: 4.Types of material availability at local market | I1: 5.Lack of consultant’s knowledge of available materials | J1: 6.Low productivity | K1: 7.Poor work execution | L1: 8.Shortage of laborers | M1: 9.Mistakes happens during construction phase | N1: 10.Unavailability of equipment | O1: 11.Lack of engineering experience | P1: 12.Construction cost underestimation | Q1: 13.Poor site management | R1: 14.Delayed payment for completed work | S1: 15.Cash flow problem during construction | T1: 16.High rate of interest | U1: 17.Contractor’s financial difficulties | V1: 18.Increase in salaries of skilled laborers | W1: 19.Change design | X1: 20.Errors and omission in design | Y1: 21.Incomplete design drawings and specifications at tendering stage | Z1: 22.Delay in preparation and approval of drawing | AA1: 23.Inaccurate quantity take-off | AB1: 24.Long period from planning of project to construction | AC1: 25.Delays in issuing information to the contractor during construction stage | AD1: 26.No practical use of earned value management system | AE1: 27.Lack of cost planning/monitoring during pre and post contract stage | AF1: 28.Poor communication between client, consultant and contractor | AG1: 29.Insufficient coordination between local authority who is responsible about road projects and service authorities | AH1: 30.Delays in decisions making by the approval authorities | AI1: 31.Change schedule | AJ1: 32.Stoppages because of work being rejected by consultant | AK1: 33.Lowest bid price | AL1: 34.Insufficient time for preparation of contract documents | AM1: 35.Discrepancies in contract documents | AN1: 36.Underestimation of time for completion of project | AO1: 37.Extension of time with cost claims | AP1: 38.Scope and specification changes | AQ1: 39.Changes in client requirements | AR1: 40.Frequency of variation orders and additional works | AS1: 41.Rework due to error in execution | AT1: 42.Weather conditions | AU1: 43.Accidents during construction | AV1: 44.Delay in getting NOCs from different government authorities | AW1: Type of Organization | AX1: Respondents designation | AY1: Indicate the highest formal qualification | AZ1: How often do you experience cost overrun | BA1: Location of organization | BB1: Relevant working experience
A2: 1.Delay in delivering material to construction site | D2: ID001 | E2: 1 | F2: 1 | G2: 1 | H2: 1 | I2: 1 | J2: 1 | K2: 1 | L2: 1 | M2: 1 | N2: 1 | O2: 1 | P2: 1 | Q2: 1 | R2: 1 | S2: 1 | T2: 1 | U2: 1 | V2: 1 | W2: 3 | X2: 3 | Y2: 3 | Z2: 4 | AA2: 4 | AB2: 3 | AC2: 3 | AD2: 2 | AE2: 1 | AF2: 2 | AG2: 4 | AH2: 4 | AI2: 1 | AJ2: 1 | AK2: 2 | AL2: 2 | AM2: 2 | AN2: 2 | AO2: 2 | AP2: 3 | AQ2: 3 | AR2: 3 | AS2: 1 | AT2: 2 | AU2: 2 | AV2: 3 | AW2: 1 | AX2: 2 | AY2: 2 | AZ2: 2 | BA2: 3 | BB2: 5
A3: 2.Monopoly of material by some suppliers | D3: ID002 | E3: 2 | F3: 5 | G3: 3 | H3: 2 | I3: 3 | J3: 2 | K3: 2 | L3: 2 | M3: 3 | N3: 2 | O3: 2 | P3: 2 | Q3: 2 | R3: 2 | S3: 2 | T3: 1 | U3: 4 | V3: 1 | W3: 5 | X3: 5 | Y3: 4 | Z3: 4 | AA3: 4 | AB3: 5 | AC3: 3 | AD3: 3 | AE3: 3 | AF3: 4 | AG3: 4 | AH3: 3 | AI3: 4 | AJ3: 4 | AK3: 5 | AL3: 3 | AM3: 4 | AN3: 4 | AO3: 4 | AP3: 3 | AQ3: 3 | AR3: 4 | AS3: 3 | AT3: 1 | AU3: 1 | AV3: 4 | AW3: 1 | AX3: 3 | AY3: 2 | AZ3: 3 | BA3: 3 | BB3: 3
A4: 3.Prices fluctuation | D4: ID003 | E4: 1 | F4: 2 | G4: 1 | H4: 1 | I4: 2 | J4: 2 | K4: 1 | L4: 2 | M4: 1 | N4: 1 | O4: 2 | P4: 1 | Q4: 3 | R4: 3 | S4: 3 | T4: 2 | U4: 2 | V4: 1 | W4: 2 | X4: 2 | Y4: 2 | Z4: 2 | AA4: 3 | AB4: 2 | AC4: 3 | AD4: 1 | AE4: 2 | AF4: 1 | AG4: 3 | AH4: 4 | AI4: 3 | AJ4: 1 | AK4: 2 | AL4: 2 | AM4: 2 | AN4: 2 | AO4: 4 | AP4: 2 | AQ4: 2 | AR4: 2 | AS4: 2 | AT4: 1 | AU4: 1 | AV4: 4 | AW4: 1 | AX4: 2 | AY4: 2 | AZ4: 1 | BA4: 2 | BB4: 4
A5: 4.Types of material availability at local market | D5: ID004 | E5: 2 | F5: 2 | G5: 3 | H5: 3 | I5: 2 | J5: 2 | K5: 3 | L5: 4 | M5: 4 | N5: 4 | O5: 2 | P5: 5 | Q5: 2 | R5: 2 | S5: 1 | T5: 1 | U5: 1 | V5: 1 | W5: 4 | X5: 4 | Y5: 4 | Z5: 4 | AA5: 4 | AB5: 3 | AC5: 2 | AD5: 2 | AE5: 2 | AF5: 2 | AG5: 3 | AH5: 3 | AI5: 2 | AJ5: 2 | AK5: 2 | AL5: 3 | AM5: 2 | AN5: 4 | AO5: 4 | AP5: 4 | AQ5: 4 | AR5: 4 | AS5: 3 | AT5: 4 | AU5: 3 | AV5: 3 | AW5: 1 | AX5: 3 | AY5: 1 | AZ5: 1 | BA5: 3 | BB5: 4
A6: 5.Lack of consultant’s knowledge of available materials | D6: ID005 | E6: 1 | F6: 2 | G6: 1 | H6: 1 | I6: 2 | J6: 2 | K6: 1 | L6: 2 | M6: 1 | N6: 1 | O6: 2 | P6: 1 | Q6: 2 | R6: 4 | S6: 4 | T6: 2 | U6: 2 | V6: 1 | W6: 2 | X6: 2 | Y6: 2 | Z6: 2 | AA6: 3 | AB6: 2 | AC6: 4 | AD6: 3 | AE6: 2 | AF6: 1 | AG6: 3 | AH6: 4 | AI6: 3 | AJ6: 1 | AK6: 2 | AL6: 2 | AM6: 2 | AN6: 2 | AO6: 4 | AP6: 2 | AQ6: 2 | AR6: 2 | AS6: 2 | AT6: 1 | AU6: 1 | AV6: 4 | AW6: 1 | AX6: 2 | AY6: 3 | AZ6: 1 | BA6: 2 | BB6: 4
A7: 6.Low productivity | D7: ID006 | E7: 1 | F7: 1 | G7: 1 | H7: 1 | I7: 1 | J7: 2 | K7: 2 | L7: 2 | M7: 1 | N7: 1 | O7: 1 | P7: 2 | Q7: 1 | R7: 4 | S7: 4 | T7: 4 | U7: 4 | V7: 1 | W7: 4 | X7: 4 | Y7: 4 | Z7: 4 | AA7: 4 | AB7: 4 | AC7: 2 | AD7: 2 | AE7: 2 | AF7: 1 | AG7: 1 | AH7: 3 | AI7: 3 | AJ7: 4 | AK7: 2 | AL7: 2 | AM7: 2 | AN7: 2 | AO7: 2 | AP7: 3 | AQ7: 2 | AR7: 3 | AS7: 3 | AT7: 2 | AU7: 2 | AV7: 2 | AW7: 1 | AX7: 4 | AY7: 2 | AZ7: 1 | BA7: 3 | BB7: 5
A8: 7.Poor work execution | D8: ID007 | E8: 1 | F8: 1 | G8: 1 | H8: 1 | I8: 1 | J8: 1 | K8: 1 | L8: 1 | M8: 1 | N8: 1 | O8: 1 | P8: 1 | Q8: 1 | R8: 4 | S8: 4 | T8: 4 | U8: 4 | V8: 1 | W8: 4 | X8: 4 | Y8: 4 | Z8: 4 | AA8: 4 | AB8: 4 | AC8: 2 | AD8: 2 | AE8: 2 | AF8: 1 | AG8: 2 | AH8: 4 | AI8: 3 | AJ8: 4 | AK8: 2 | AL8: 2 | AM8: 2 | AN8: 2 | AO8: 4 | AP8: 4 | AQ8: 3 | AR8: 4 | AS8: 4 | AT8: 2 | AU8: 2 | AV8: 2 | AW8: 1 | AX8: 5 | AY8: 2 | AZ8: 1 | BA8: 3 | BB8: 5
A9: 8.Shortage of laborers | D9: ID008 | E9: 1 | F9: 1 | G9: 1 | H9: 1 | I9: 1 | J9: 1 | K9: 1 | L9: 1 | M9: 1 | N9: 1 | O9: 1 | P9: 1 | Q9: 1 | R9: 3 | S9: 3 | T9: 3 | U9: 4 | V9: 4 | W9: 4 | X9: 4 | Y9: 4 | Z9: 4 | AA9: 4 | AB9: 4 | AC9: 2 | AD9: 2 | AE9: 2 | AF9: 1 | AG9: 1 | AH9: 3 | AI9: 3 | AJ9: 4 | AK9: 2 | AL9: 2 | AM9: 2 | AN9: 2 | AO9: 2 | AP9: 3 | AQ9: 2 | AR9: 3 | AS9: 3 | AT9: 2 | AU9: 2 | AV9: 2 | AW9: 1 | AX9: 4 | AY9: 2 | AZ9: 1 | BA9: 3 | BB9: 5
A10: 9.Mistakes happens during construction phase | D10: ID009 | E10: 1 | F10: 1 | G10: 1 | H10: 1 | I10: 1 | J10: 1 | K10: 1 | L10: 1 | M10: 1 | N10: 1 | O10: 1 | P10: 1 | Q10: 1 | R10: 4 | S10: 4 | T10: 4 | U10: 4 | V10: 3 | W10: 4 | X10: 4 | Y10: 4 | Z10: 4 | AA10: 4 | AB10: 4 | AC10: 2 | AD10: 2 | AE10: 2 | AF10: 1 | AG10: 2 | AH10: 4 | AI10: 3 | AJ10: 4 | AK10: 2 | AL10: 2 | AM10: 2 | AN10: 2 | AO10: 2 | AP10: 4 | AQ10: 3 | AR10: 4 | AS10: 4 | AT10: 2 | AU10: 2 | AV10: 2 | AW10: 1 | AX10: 4 | AY10: 2 | AZ10: 1 | BA10: 3 | BB10: 5
A11: 10.Unavailability of equipment | D11: ID010 | E11: 1 | F11: 1 | G11: 1 | H11: 1 | I11: 1 | J11: 1 | K11: 1 | L11: 1 | M11: 1 | N11: 1 | O11: 1 | P11: 1 | Q11: 1 | R11: 4 | S11: 4 | T11: 4 | U11: 4 | V11: 2 | W11: 4 | X11: 4 | Y11: 4 | Z11: 4 | AA11: 4 | AB11: 4 | AC11: 2 | AD11: 2 | AE11: 2 | AF11: 1 | AG11: 1 | AH11: 3 | AI11: 3 | AJ11: 4 | AK11: 2 | AL11: 2 | AM11: 2 | AN11: 2 | AO11: 2 | AP11: 3 | AQ11: 2 | AR11: 3 | AS11: 3 | AT11: 2 | AU11: 2 | AV11: 2 | AW11: 1 | AX11: 4 | AY11: 2 | AZ11: 1 | BA11: 3 | BB11: 5
A12: 11.Lack of engineering experience | D12: ID011 | E12: 2 | F12: 4 | G12: 4 | H12: 1 | I12: 1 | J12: 5 | K12: 1 | L12: 4 | M12: 5 | N12: 3 | O12: 2 | P12: 5 | Q12: 2 | R12: 1 | S12: 1 | T12: 1 | U12: 1 | V12: 3 | W12: 5 | X12: 2 | Y12: 3 | Z12: 4 | AA12: 3 | AB12: 2 | AC12: 2 | AD12: 1 | AE12: 2 | AF12: 1 | AG12: 5 | AH12: 1 | AI12: 1 | AJ12: 1 | AK12: 1 | AL12: 1 | AM12: 1 | AN12: 3 | AO12: 3 | AP12: 4 | AQ12: 4 | AR12: 4 | AS12: 1 | AT12: 1 | AU12: 1 | AV12: 1 | AW12: 1 | AX12: 5 | AY12: 3 | AZ12: 2 | BA12: 3 | BB12: 4
A13: 12.Construction cost underestimation | D13: ID012 | E13: 2 | F13: 1 | G13: 3 | H13: 4 | I13: 4 | J13: 3 | K13: 3 | L13: 4 | M13: 3 | N13: 4 | O13: 5 | P13: 4 | Q13: 3 | R13: 3 | S13: 4 | T13: 2 | U13: 4 | V13: 2 | W13: 4 | X13: 4 | Y13: 5 | Z13: 3 | AA13: 4 | AB13: 3 | AC13: 3 | AD13: 3 | AE13: 3 | AF13: 4 | AG13: 4 | AH13: 4 | AI13: 3 | AJ13: 4 | AK13: 4 | AL13: 3 | AM13: 3 | AN13: 4 | AO13: 4 | AP13: 4 | AQ13: 4 | AR13: 4 | AS13: 4 | AT13: 2 | AU13: 2 | AV13: 3 | AW13: 1 | AX13: 2 | AY13: 2 | AZ13: 1 | BA13: 3 | BB13: 5
... A44: 43.Accidents during construction | D44: ID043 | E44: 4 | F44: 5 | G44: 3 | H44: 4 | I44: 4 | J44: 4 | K44: 5 | L44: 4 | M44: 4 | N44: 4 | O44: 4 | P44: 4 | Q44: 4 | R44: 5 | S44: 5 | T44: 5 | U44: 4 | V44: 3 | W44: 5 | X44: 4 | Y44: 4 | Z44: 4 | AA44: 4 | AB44: 3 | AC44: 4 | AD44: 3 | AE44: 4 | AF44: 4 | AG44: 4 | AH44: 4 | AI44: 4 | AJ44: 4 | AK44: 1 | AL44: 2 | AM44: 3 | AN44: 4 | AO44: 5 | AP44: 4 | AQ44: 5 | AR44: 4 | AS44: 4 | AT44: 3 | AU44: 3 | AV44: 5 | AW44: 1 | AX44: 3 | AY44: 3 | AZ44: 1 | BA44: 2 | BB44: 4
A45: 44.Delay in getting NOCs from different government authorities | D45: ID044 | E45: 4 | F45: 5 | G45: 3 | H45: 4 | I45: 4 | J45: 4 | K45: 5 | L45: 4 | M45: 4 | N45: 5 | O45: 4 | P45: 4 | Q45: 4 | R45: 5 | S45: 5 | T45: 5 | U45: 4 | V45: 3 | W45: 5 | X45: 4 | Y45: 4 | Z45: 4 | AA45: 4 | AB45: 3 | AC45: 4 | AD45: 3 | AE45: 4 | AF45: 3 | AG45: 3 | AH45: 4 | AI45: 4 | AJ45: 4 | AL45: 5 | AM45: 4 | AN45: 3 | AO45: 4 | AP45: 5 | AQ45: 4 | AR45: 5 | AS45: 3 | AT45: 2 | AU45: 2 | AV45: 5 | AW45: 1 | AX45: 3 | AY45: 2 | AZ45: 1 | BA45: 1 | BB45: 4
A46: Type of Organization | D46: ID045 | E46: 4 | F46: 5 | G46: 3 | H46: 4 | I46: 4 | J46: 4 | K46: 5 | L46: 4 | M46: 4 | N46: 5 | O46: 4 | P46: 4 | Q46: 4 | R46: 5 | S46: 5 | T46: 5 | U46: 4 | V46: 3 | W46: 5 | X46: 4 | Y46: 4 | Z46: 4 | AA46: 4 | AB46: 3 | AC46: 4 | AD46: 3 | AE46: 4 | AF46: 3 | AG46: 3 | AH46: 4 | AI46: 4 | AJ46: 4 | AK46: 5 | AL46: 4 | AM46: 3 | AN46: 4 | AO46: 5 | AP46: 4 | AQ46: 5 | AR46: 4 | AS46: 4 | AT46: 3 | AU46: 3 | AV46: 5 | AW46: 2 | AX46: 3 | AY46: 3 | AZ46: 1 | BA46: 1 | BB46: 4
A47: Respondents designation | D47: ID046 | E47: 4 | F47: 5 | G47: 3 | H47: 4 | I47: 4 | J47: 4 | K47: 5 | L47: 4 | M47: 4 | N47: 5 | O47: 4 | P47: 4 | Q47: 4 | R47: 5 | S47: 5 | T47: 5 | U47: 4 | V47: 3 | W47: 5 | X47: 4 | Y47: 4 | Z47: 4 | AA47: 4 | AB47: 3 | AC47: 4 | AD47: 3 | AE47: 4 | AF47: 4 | AG47: 4 | AH47: 5 | AI47: 4 | AJ47: 4 | AK47: 5 | AL47: 4 | AM47: 3 | AN47: 4 | AO47: 5 | AP47: 4 | AQ47: 5 | AR47: 4 | AS47: 4 | AT47: 3 | AU47: 3 | AV47: 5 | AW47: 2 | AX47: 2 | AY47: 3 | AZ47: 1 | BA47: 3 | BB47: 4
A48: Indicate the highest formal qualification | D48: ID047 | E48: 4 | F48: 3 | G48: 3 | H48: 3 | I48: 3 | J48: 5 | K48: 5 | L48: 5 | M48: 5 | N48: 5 | O48: 4 | P48: 4 | Q48: 4 | R48: 4 | S48: 4 | T48: 3 | U48: 3 | V48: 3 | W48: 3 | X48: 2 | Y48: 2 | Z48: 4 | AA48: 3 | AB48: 2 | AC48: 3 | AD48: 4 | AE48: 4 | AF48: 5 | AG48: 5 | AH48: 5 | AI48: 4 | AJ48: 4 | AK48: 3 | AL48: 4 | AM48: 4 | AN48: 5 | AO48: 4 | AP48: 5 | AQ48: 3 | AR48: 3 | AS48: 4 | AT48: 3 | AU48: 2 | AV48: 4 | AW48: 2 | AX48: 2 | AY48: 2 | AZ48: 2 | BA48: 3 | BB48: 4
A49: How often do you experience cost overrun | D49: ID048 | E49: 1 | F49: 1 | G49: 2 | H49: 2 | I49: 2 | J49: 4 | K49: 4 | L49: 3 | M49: 4 | N49: 4 | O49: 5 | P49: 5 | Q49: 5 | R49: 5 | S49: 5 | T49: 5 | U49: 4 | V49: 3 | W49: 3 | X49: 4 | Y49: 3 | Z49: 4 | AA49: 4 | AB49: 4 | AC49: 3 | AD49: 2 | AE49: 4 | AF49: 5 | AG49: 5 | AH49: 5 | AI49: 3 | AJ49: 2 | AK49: 4 | AL49: 5 | AM49: 5 | AN49: 4 | AO49: 5 | AP49: 5 | AQ49: 5 | AR49: 4 | AS49: 5 | AT49: 3 | AU49: 5 | AV49: 4 | AW49: 2 | AX49: 5 | AY49: 2 | AZ49: 1 | BA49: 1 | BB49: 5
A50: Location of organization | D50: ID049 | E50: 4 | F50: 2 | G50: 4 | H50: 4 | I50: 3 | J50: 4 | K50: 5 | L50: 3 | M50: 5 | N50: 3 | O50: 5 | P50: 5 | Q50: 5 | R50: 4 | S50: 4 | T50: 3 | U50: 2 | V50: 2 | W50: 4 | X50: 5 | Y50: 4 | Z50: 4 | AA50: 4 | AB50: 4 | AC50: 3 | AD50: 3 | AE50: 4 | AF50: 4 | AG50: 5 | AH50: 5 | AI50: 3 | AJ50: 3 | AK50: 4 | AL50: 3 | AM50: 4 | AN50: 4 | AO50: 3 | AP50: 4 | AQ50: 4 | AR50: 4 | AS50: 4 | AT50: 3 | AU50: 3 | AV50: 3 | AW50: 2 | AX50: 5 | AY50: 3 | AZ50: 2 | BA50: 3 | BB50: 3
A51: Relevant working experience | D51: ID050 | E51: 5 | F51: 4 | G51: 4 | H51: 5 | I51: 2 | J51: 5 | K51: 5 | L51: 5 | M51: 4 | N51: 4 | O51: 4 | P51: 4 | Q51: 5 | R51: 3 | S51: 5 | T51: 4 | U51: 5 | V51: 3 | W51: 4 | X51: 4 | Y51: 4 | Z51: 4 | AA51: 4 | AB51: 4 | AC51: 5 | AD51: 4 | AE51: 5 | AF51: 5 | AG51: 4 | AH51: 5 | AI51: 5 | AJ51: 4 | AK51: 4 | AL51: 5 | AM51: 4 | AN51: 4 | AO51: 4 | AP51: 5 | AQ51: 4 | AR51: 5 | AS51: 4 | AT51: 4 | AU51: 4 | AV51: 4 | AW51: 2 | AX51: 5 | AY51: 3 | AZ51: 1 | BA51: 1 | BB51: 4
D52: ID051 | E52: 4 | F52: 2 | G52: 4 | H52: 3 | I52: 3 | J52: 4 | K52: 4 | L52: 3 | M52: 4 | N52: 3 | O52: 3 | P52: 5 | Q52: 4 | R52: 2 | S52: 2 | T52: 3 | U52: 3 | V52: 3 | W52: 4 | X52: 3 | Y52: 2 | Z52: 3 | AA52: 4 | AB52: 4 | AC52: 3 | AD52: 3 | AE52: 3 | AF52: 2 | AG52: 2 | AH52: 3 | AI52: 4 | AJ52: 4 | AK52: 4 | AL52: 3 | AM52: 3 | AN52: 4 | AO52: 3 | AP52: 4 | AQ52: 4 | AR52: 3 | AS52: 4 | AT52: 3 | AU52: 3 | AV52: 2 | AW52: 2 | AX52: 5 | AY52: 2 | AZ52: 1 | BA52: 3 | BB52: 4
D53: ID052 | E53: 5 | F53: 4 | G53: 4 | H53: 5 | I53: 2 | J53: 5 | K53: 5 | L53: 5 | M53: 4 | N53: 4 | O53: 4 | P53: 4 | Q53: 5 | R53: 4 | S53: 5 | T53: 4 | U53: 5 | V53: 3 | W53: 4 | X53: 4 | Y53: 4 | Z53: 4 | AA53: 4 | AB53: 4 | AC53: 5 | AD53: 4 | AE53: 5 | AF53: 5 | AG53: 4 | AH53: 5 | AI53: 5 | AJ53: 4 | AK53: 4 | AL53: 5 | AM53: 4 | AN53: 4 | AO53: 4 | AP53: 4 | AQ53: 5 | AR53: 4 | AS53: 5 | AT53: 4 | AU53: 4 | AV53: 4 | AW53: 2 | AX53: 4 | AY53: 2 | AZ53: 1 | BA53: 3 | BB53: 3
D54: ID053 | E54: 5 | F54: 4 | G54: 1 | H54: 3 | I54: 1 | J54: 4 | K54: 4 | L54: 4 | M54: 4 | N54: 4 | O54: 4 | P54: 3 | Q54: 3 | R54: 3 | S54: 3 | T54: 2 | U54: 4 | V54: 2 | W54: 3 | X54: 3 | Y54: 1 | Z54: 2 | AA54: 3 | AB54: 4 | AC54: 3 | AD54: 2 | AE54: 3 | AF54: 3 | AG54: 4 | AH54: 5 | AI54: 1 | AJ54: 2 | AK54: 3 | AL54: 2 | AM54: 3 | AN54: 5 | AO54: 4 | AP54: 2 | AQ54: 3 | AR54: 3 | AS54: 3 | AT54: 2 | AU54: 2 | AV54: 4 | AW54: 2 | AX54: 3 | AY54: 2 | AZ54: 2 | BA54: 3 | BB54: 5
D55: ID054 | E55: 4 | F55: 5 | G55: 3 | H55: 4 | I55: 4 | J55: 4 | K55: 5 | L55: 4 | M55: 4 | N55: 5 | O55: 4 | P55: 4 | Q55: 4 | R55: 5 | S55: 5 | T55: 5 | U55: 4 | V55: 3 | W55: 5 | X55: 4 | Y55: 4 | Z55: 4 | AA55: 4 | AB55: 3 | AC55: 4 | AD55: 3 | AE55: 4 | AF55: 4 | AG55: 4 | AH55: 5 | AI55: 4 | AJ55: 4 | AK55: 5 | AL55: 4 | AM55: 3 | AN55: 4 | AO55: 5 | AP55: 4 | AQ55: 5 | AR55: 4 | AS55: 4 | AT55: 3 | AU55: 3 | AV55: 5 | AW55: 2 | AX55: 2 | AY55: 3 | AZ55: 1 | BA55: 3 | BB55: 4
D56: ID055 | E56: 2 | F56: 3 | G56: 4 | H56: 2 | I56: 4 | J56: 3 | K56: 2 | L56: 3 | M56: 4 | N56: 3 | O56: 4 | P56: 5 | Q56: 5 | R56: 3 | S56: 5 | T56: 4 | U56: 5 | V56: 4 | W56: 5 | X56: 4 | Y56: 5 | Z56: 3 | AA56: 5 | AB56: 5 | AC56: 3 | AD56: 4 | AE56: 4 | AF56: 3 | AG56: 3 | AH56: 4 | AI56: 3 | AJ56: 3 | AK56: 3 | AL56: 4 | AM56: 3 | AN56: 4 | AO56: 4 | AP56: 4 | AQ56: 5 | AR56: 4 | AS56: 4 | AT56: 3 | AU56: 3 | AV56: 3 | AW56: 2 | AX56: 3 | AY56: 2 | AZ56: 1 | BA56: 3 | BB56: 5
D57: ID056 | E57: 1 | F57: 1 | G57: 1 | H57: 1 | I57: 1 | J57: 5 | K57: 5 | L57: 3 | M57: 2 | N57: 5 | O57: 5 | P57: 5 | Q57: 4 | R57: 5 | S57: 5 | T57: 5 | U57: 5 | V57: 3 | W57: 5 | X57: 4 | Y57: 4 | Z57: 3 | AA57: 1 | AB57: 1 | AC57: 2 | AD57: 2 | AE57: 5 | AF57: 5 | AG57: 5 | AH57: 5 | AI57: 2 | AJ57: 2 | AK57: 3 | AL57: 5 | AM57: 4 | AN57: 5 | AO57: 3 | AP57: 4 | AQ57: 5 | AR57: 4 | AS57: 5 | AT57: 2 | AU57: 1 | AV57: 5 | AW57: 2 | AX57: 3 | AY57: 2 | AZ57: 1 | BA57: 1 | BB57: 5
D58: ID057 | E58: 1 | F58: 1 | G58: 4 | H58: 3 | I58: 4 | J58: 4 | K58: 4 | L58: 4 | M58: 5 | N58: 3 | O58: 3 | P58: 5 | Q58: 5 | R58: 4 | S58: 2 | T58: 3 | U58: 2 | V58: 5 | W58: 5 | X58: 4 | Y58: 3 | Z58: 5 | AA58: 5 | AB58: 4 | AC58: 4 | AD58: 3 | AE58: 4 | AF58: 4 | AG58: 3 | AH58: 5 | AI58: 5 | AJ58: 3 | AK58: 3 | AL58: 2 | AM58: 2 | AN58: 5 | AO58: 3 | AP58: 4 | AQ58: 5 | AR58: 4 | AS58: 3 | AT58: 2 | AU58: 2 | AV58: 4 | AW58: 2 | AX58: 5 | AY58: 2 | AZ58: 1 | BA58: 3 | BB58: 4
D59: ID058 | E59: 1 | F59: 1 | G59: 4 | H59: 3 | I59: 4 | J59: 4 | K59: 4 | L59: 4 | M59: 5 | N59: 3 | O59: 3 | P59: 5 | Q59: 5 | R59: 3 | S59: 2 | T59: 4 | U59: 2 | V59: 5 | W59: 5 | X59: 4 | Y59: 3 | Z59: 5 | AA59: 5 | AB59: 3 | AC59: 3 | AD59: 5 | AE59: 3 | AF59: 4 | AG59: 4 | AH59: 5 | AI59: 5 | AJ59: 3 | AK59: 3 | AL59: 4 | AM59: 4 | AN59: 3 | AO59: 1 | AP59: 4 | AQ59: 5 | AR59: 4 | AS59: 3 | AT59: 2 | AU59: 2 | AV59: 4 | AW59: 2 | AX59: 5 | AY59: 2 | AZ59: 1 | BA59: 3 | BB59: 4
D60: ID059 | E60: 1 | F60: 1 | G60: 4 | H60: 3 | I60: 4 | J60: 4 | K60: 4 | L60: 4 | M60: 5 | N60: 3 | O60: 3 | P60: 5 | Q60: 5 | R60: 3 | S60: 2 | T60: 4 | U60: 2 | V60: 5 | W60: 5 | X60: 4 | Y60: 3 | Z60: 5 | AA60: 5 | AB60: 3 | AC60: 3 | AD60: 5 | AE60: 3 | AF60: 4 | AG60: 4 | AH60: 5 | AI60: 5 | AJ60: 3 | AK60: 3 | AL60: 4 | AM60: 4 | AN60: 5 | AO60: 3 | AP60: 4 | AQ60: 5 | AR60: 4 | AS60: 3 | AT60: 2 | AU60: 2 | AV60: 4 | AW60: 2 | AX60: 5 | AY60: 2 | AZ60: 1 | BA60: 1 | BB60: 4
D61: ID060 | E61: 4 | F61: 5 | G61: 3 | H61: 4 | I61: 4 | J61: 4 | K61: 5 | L61: 4 | M61: 4 | N61: 5 | O61: 4 | P61: 4 | Q61: 4 | R61: 5 | S61: 5 | T61: 5 | U61: 4 | V61: 3 | W61: 5 | X61: 4 | Y61: 4 | Z61: 4 | AA61: 4 | AB61: 3 | AC61: 4 | AD61: 3 | AE61: 4 | AF61: 3 | AG61: 3 | AH61: 4 | AI61: 4 | AJ61: 4 | AK61: 5 | AL61: 4 | AM61: 3 | AN61: 4 | AO61: 5 | AP61: 4 | AQ61: 5 | AR61: 4 | AS61: 4 | AT61: 3 | AU61: 3 | AV61: 5 | AW61: 2 | AX61: 3 | AY61: 3 | AZ61: 1 | BA61: 1 | BB61: 4
D62: ID061 | E62: 4 | F62: 5 | G62: 3 | H62: 4 | I62: 4 | J62: 4 | K62: 5 | L62: 4 | M62: 4 | N62: 5 | O62: 4 | P62: 4 | Q62: 4 | R62: 5 | S62: 5 | T62: 5 | U62: 4 | V62: 3 | W62: 5 | X62: 4 | Y62: 4 | Z62: 4 | AA62: 4 | AB62: 3 | AC62: 4 | AD62: 3 | AE62: 4 | AF62: 3 | AG62: 3 | AH62: 4 | AI62: 4 | AJ62: 4 | AK62: 5 | AL62: 4 | AM62: 3 | AN62: 4 | AO62: 5 | AP62: 4 | AQ62: 5 | AR62: 4 | AS62: 4 | AT62: 3 | AU62: 3 | AV62: 5 | AW62: 2 | AX62: 3 | AY62: 2 | AZ62: 1 | BA62: 2 | BB62: 4
D63: ID062 | E63: 5 | F63: 4 | G63: 1 | H63: 3 | I63: 1 | J63: 4 | K63: 4 | L63: 4 | M63: 4 | N63: 4 | O63: 4 | P63: 3 | Q63: 3 | R63: 3 | S63: 3 | T63: 2 | U63: 4 | V63: 2 | W63: 3 | X63: 3 | Y63: 1 | Z63: 2 | AA63: 3 | AB63: 4 | AC63: 3 | AD63: 2 | AE63: 3 | AF63: 3 | AG63: 4 | AH63: 5 | AI63: 1 | AJ63: 2 | AK63: 3 | AL63: 2 | AM63: 3 | AN63: 5 | AO63: 4 | AP63: 2 | AQ63: 3 | AR63: 3 | AS63: 3 | AT63: 2 | AU63: 2 | AV63: 4 | AW63: 2 | AX63: 5 | AY63: 2 | AZ63: 2 | BA63: 1 | BB63: 5
... D72: ID071 | E72: 4 | F72: 4 | G72: 3 | H72: 4 | I72: 4 | J72: 4 | K72: 4 | L72: 4 | M72: 4 | N72: 4 | O72: 4 | P72: 4 | Q72: 4 | R72: 4 | S72: 4 | T72: 4 | U72: 4 | V72: 4 | W72: 4 | X72: 4 | Y72: 4 | Z72: 4 | AA72: 4 | AB72: 3 | AC72: 3 | AD72: 3 | AE72: 4 | AF72: 5 | AG72: 4 | AH72: 5 | AI72: 3 | AJ72: 4 | AK72: 4 | AL72: 5 | AM72: 4 | AN72: 4 | AO72: 4 | AP72: 4 | AQ72: 4 | AR72: 5 | AS72: 5 | AT72: 4 | AU72: 4 | AV72: 5 | AW72: 2 | AX72: 2 | AY72: 3 | AZ72: 2 | BA72: 1 | BB72: 5
D73: ID072 | E73: 3 | F73: 3 | G73: 3 | H73: 3 | I73: 3 | J73: 3 | K73: 2 | L73: 3 | M73: 2 | N73: 3 | O73: 3 | P73: 3 | Q73: 4 | R73: 4 | S73: 4 | T73: 4 | U73: 5 | V73: 4 | X73: 2 | Y73: 2 | Z73: 3 | AA73: 3 | AB73: 2 | AC73: 3 | AD73: 3 | AE73: 4 | AF73: 3 | AG73: 3 | AH73: 4 | AI73: 3 | AJ73: 3 | AK73: 3 | AL73: 2 | AM73: 2 | AN73: 4 | AO73: 5 | AP73: 4 | AQ73: 5 | AR73: 5 | AS73: 2 | AT73: 2 | AU73: 2 | AV73: 4 | AW73: 2 | AX73: 2 | AY73: 3 | AZ73: 2 | BA73: 3 | BB73: 5
D74: ID073 | E74: 1 | F74: 1 | G74: 5 | H74: 1 | I74: 1 | J74: 5 | K74: 5 | L74: 5 | M74: 5 | N74: 5 | O74: 5 | P74: 5 | Q74: 5 | R74: 4 | S74: 4 | T74: 4 | U74: 4 | V74: 4 | W74: 5 | X74: 5 | Y74: 5 | Z74: 5 | AA74: 5 | AB74: 5 | AC74: 5 | AD74: 3 | AE74: 3 | AF74: 3 | AG74: 5 | AH74: 5 | AI74: 3 | AJ74: 3 | AK74: 1 | AL74: 1 | AM74: 1 | AN74: 1 | AO74: 1 | AP74: 5 | AQ74: 5 | AR74: 5 | AS74: 5 | AT74: 1 | AU74: 1 | AV74: 1 | AW74: 2 | AX74: 4 | AY74: 3 | AZ74: 2 | BA74: 3 | BB74: 4
D75: ID074 | E75: 4 | F75: 4 | G75: 1 | H75: 3 | I75: 3 | J75: 4 | K75: 4 | L75: 5 | M75: 4 | N75: 5 | O75: 3 | P75: 5 | Q75: 5 | R75: 3 | S75: 5 | T75: 3 | U75: 4 | V75: 2 | W75: 5 | X75: 5 | Y75: 4 | Z75: 5 | AA75: 4 | AB75: 3 | AC75: 5 | AD75: 3 | AE75: 5 | AF75: 3 | AG75: 4 | AH75: 4 | AI75: 3 | AJ75: 4 | AK75: 5 | AL75: 5 | AM75: 5 | AN75: 3 | AO75: 2 | AP75: 5 | AQ75: 5 | AR75: 5 | AS75: 4 | AT75: 3 | AU75: 3 | AV75: 4 | AW75: 2 | AX75: 4 | AY75: 3 | AZ75: 2 | BA75: 1 | BB75: 4
D76: ID075 | E76: 4 | F76: 4 | G76: 1 | H76: 3 | I76: 3 | J76: 4 | K76: 4 | L76: 3 | M76: 4 | N76: 5 | O76: 3 | P76: 5 | Q76: 5 | R76: 3 | S76: 4 | T76: 2 | U76: 4 | V76: 2 | W76: 3 | X76: 3 | Y76: 4 | Z76: 5 | AA76: 4 | AB76: 3 | AC76: 5 | AD76: 3 | AE76: 5 | AF76: 4 | AG76: 4 | AH76: 4 | AI76: 4 | AJ76: 5 | AK76: 2 | AL76: 2 | AM76: 2 | AN76: 5 | AO76: 3 | AP76: 4 | AQ76: 4 | AR76: 4 | AS76: 4 | AT76: 3 | AU76: 3 | AV76: 4 | AW76: 2 | AX76: 5 | AY76: 2 | AZ76: 2 | BA76: 3 | BB76: 4
D77: ID076 | E77: 3 | F77: 1 | G77: 1 | H77: 2 | I77: 1 | J77: 1 | K77: 1 | L77: 3 | M77: 1 | N77: 5 | O77: 1 | P77: 3 | Q77: 1 | R77: 5 | S77: 4 | T77: 2 | U77: 5 | V77: 5 | W77: 1 | X77: 1 | Y77: 3 | Z77: 5 | AA77: 3 | AB77: 3 | AC77: 2 | AD77: 3 | AE77: 3 | AF77: 5 | AG77: 5 | AH77: 5 | AI77: 5 | AJ77: 2 | AK77: 5 | AL77: 2 | AM77: 2 | AN77: 1 | AO77: 4 | AP77: 5 | AQ77: 5 | AR77: 5 | AS77: 1 | AT77: 2 | AU77: 2 | AV77: 5 | AW77: 2 | AX77: 2 | AY77: 3 | AZ77: 2 | BA77: 1 | BB77: 3
D78: ID077 | E78: 5 | F78: 3 | G78: 3 | H78: 3 | I78: 2 | J78: 5 | K78: 4 | L78: 4 | M78: 4 | N78: 4 | O78: 4 | P78: 5 | Q78: 4 | R78: 3 | S78: 3 | T78: 2 | U78: 3 | V78: 1 | W78: 5 | X78: 5 | Y78: 5 | Z78: 5 | AA78: 5 | AB78: 5 | AC78: 5 | AD78: 4 | AE78: 5 | AF78: 4 | AG78: 4 | AH78: 5 | AI78: 5 | AJ78: 4 | AK78: 5 | AL78: 5 | AM78: 5 | AN78: 5 | AO78: 4 | AP78: 5 | AQ78: 5 | AR78: 5 | AS78: 5 | AT78: 3 | AU78: 3 | AV78: 4 | AW78: 2 | AX78: 4 | AY78: 2 | AZ78: 2 | BA78: 2 | BB78: 3
...

Sheet 3rd Iteration Dataset
A1: ID | B1: 1.Delay in delivering material to construction site | C1: 2.Monopoly of material by some suppliers | D1: 3.Prices fluctuation | E1: 4.Types of material availability at local market | F1: 5.Lack of consultant’s knowledge of available materials | G1: 6.Low productivity | H1: 7.Poor work execution | I1: 8.Shortage of laborers | J1: 9.Mistakes happens during construction phase | K1: 10.Unavailability of equipment | L1: 11.Lack of engineering experience | M1: 12.Construction cost underestimation | N1: 13.Poor site management | O1: 14.Delayed payment for completed work | P1: 15.Cash flow problem during construction | Q1: 16.High rate of interest | R1: 17.Contractor’s financial difficulties | S1: 19.Change design | T1: 20.Errors and omission in design | U1: 21.Incomplete design drawings and specifications at tendering stage | V1: 22.Delay in preparation and approval of drawing | W1: 23.Inaccurate quantity take-off | X1: 24.Long period from planning of project to construction | Y1: 25.Delays in issuing information to the contractor during construction stage | Z1: 26.No practical use of earned value management system | AA1: 27.Lack of cost planning/monitoring during pre and post contract stage | AB1: 28.Poor communication between client, consultant and contractor | AC1: 29.Insufficient coordination between local authority who is responsible about road projects and service authorities | AD1: 30.Delays in decisions making by the approval authorities | AE1: 31.Change schedule | AF1: 32.Stoppages because of work being rejected by consultant | AG1: 33.Lowest bid price | AH1: 34.Insufficient time for preparation of contract documents | AI1: 35.Discrepancies in contract documents | AJ1: 36.Underestimation of time for completion of project | AK1: 37.Extension of time with cost claims | AL1: 38.Scope and specification changes | AM1: 39.Changes in client requirements | AN1: 40.Frequency of variation orders and additional works | AO1: 41.Rework due to error in execution | AP1: 42.Weather conditions | AQ1: 43.Accidents during construction | AR1: 44.Delay in getting NOCs from different government authorities | AS1: Location of organization | AT1: Relevant working experience
A2: ID001 | B2: 1 | C2: 1 | D2: 1 | E2: 1 | F2: 1 | G2: 1 | H2: 1 | I2: 1 | J2: 1 | K2: 1 | L2: 1 | M2: 1 | N2: 1 | O2: 1 | P2: 1 | Q2: 1 | R2: 1 | S2: 3 | T2: 3 | U2: 3 | V2: 4 | W2: 4 | X2: 3 | Y2: 3 | Z2: 2 | AA2: 1 | AB2: 2 | AC2: 4 | AD2: 4 | AE2: 1 | AF2: 1 | AG2: 2 | AH2: 2 | AI2: 2 | AJ2: 2 | AK2: 2 | AL2: 3 | AM2: 3 | AN2: 3 | AO2: 1 | AP2: 2 | AQ2: 2 | AR2: 3 | AS2: 3 | AT2: 5
A3: ID002 | B3: 2 | C3: 5 | D3: 3 | E3: 2 | F3: 3 | G3: 2 | H3: 2 | I3: 2 | J3: 3 | K3: 2 | L3: 2 | M3: 2 | N3: 2 | O3: 2 | P3: 2 | Q3: 1 | R3: 4 | S3: 5 | T3: 5 | U3: 4 | V3: 4 | W3: 4 | X3: 5 | Y3: 3 | Z3: 3 | AA3: 3 | AB3: 4 | AC3: 4 | AD3: 3 | AE3: 4 | AF3: 4 | AG3: 5 | AH3: 3 | AI3: 4 | AJ3: 4 | AK3: 4 | AL3: 3 | AM3: 3 | AN3: 4 | AO3: 3 | AP3: 1 | AQ3: 1 | AR3: 4 | AS3: 3 | AT3: 3
A4: ID003 | B4: 1 | C4: 2 | D4: 1 | E4: 1 | F4: 2 | G4: 2 | H4: 1 | I4: 2 | J4: 1 | K4: 1 | L4: 2 | M4: 1 | N4: 3 | O4: 3 | P4: 3 | Q4: 2 | R4: 2 | S4: 2 | T4: 2 | U4: 2 | V4: 2 | W4: 3 | X4: 2 | Y4: 3 | Z4: 1 | AA4: 2 | AB4: 1 | AC4: 3 | AD4: 4 | AE4: 3 | AF4: 1 | AG4: 2 | AH4: 2 | AI4: 2 | AJ4: 2 | AK4: 4 | AL4: 2 | AM4: 2 | AN4: 2 | AO4: 2 | AP4: 1 | AQ4: 1 | AR4: 4 | AS4: 2 | AT4: 4
A5: ID004 | B5: 2 | C5: 2 | D5: 3 | E5: 3 | F5: 2 | G5: 2 | H5: 3 | I5: 4 | J5: 4 | K5: 4 | L5: 2 | M5: 5 | N5: 2 | O5: 2 | P5: 1 | Q5: 1 | R5: 1 | S5: 4 | T5: 4 | U5: 4 | V5: 4 | W5: 4 | X5: 3 | Y5: 2 | Z5: 2 | AA5: 2 | AB5: 2 | AC5: 3 | AD5: 3 | AE5: 2 | AF5: 2 | AG5: 2 | AH5: 3 | AI5: 2 | AJ5: 4 | AK5: 4 | AL5: 4 | AM5: 4 | AN5: 4 | AO5: 3 | AP5: 4 | AQ5: 3 | AR5: 3 | AS5: 3 | AT5: 4
A6: ID005 | B6: 1 | C6: 2 | D6: 1 | E6: 1 | F6: 2 | G6: 2 | H6: 1 | I6: 2 | J6: 1 | K6: 1 | L6: 2 | M6: 1 | N6: 2 | O6: 4 | P6: 4 | Q6: 2 | R6: 2 | S6: 2 | T6: 2 | U6: 2 | V6: 2 | W6: 3 | X6: 2 | Y6: 4 | Z6: 3 | AA6: 2 | AB6: 1 | AC6: 3 | AD6: 4 | AE6: 3 | AF6: 1 | AG6: 2 | AH6: 2 | AI6: 2 | AJ6: 2 | AK6: 4 | AL6: 2 | AM6: 2 | AN6: 2 | AO6: 2 | AP6: 1 | AQ6: 1 | AR6: 4 | AS6: 2 | AT6: 4
A7: ID006 | B7: 1 | C7: 1 | D7: 1 | E7: 1 | F7: 1 | G7: 2 | H7: 2 | I7: 2 | J7: 1 | K7: 1 | L7: 1 | M7: 2 | N7: 1 | O7: 4 | P7: 4 | Q7: 4 | R7: 4 | S7: 4 | T7: 4 | U7: 4 | V7: 4 | W7: 4 | X7: 4 | Y7: 2 | Z7: 2 | AA7: 2 | AB7: 1 | AC7: 1 | AD7: 3 | AE7: 3 | AF7: 4 | AG7: 2 | AH7: 2 | AI7: 2 | AJ7: 2 | AK7: 2 | AL7: 3 | AM7: 2 | AN7: 3 | AO7: 3 | AP7: 2 | AQ7: 2 | AR7: 2 | AS7: 3 | AT7: 5
A8: ID007 | B8: 1 | C8: 1 | D8: 1 | E8: 1 | F8: 1 | G8: 1 | H8: 1 | I8: 1 | J8: 1 | K8: 1 | L8: 1 | M8: 1 | N8: 1 | O8: 4 | P8: 4 | Q8: 4 | R8: 4 | S8: 4 | T8: 4 | U8: 4 | V8: 4 | W8: 4 | X8: 4 | Y8: 2 | Z8: 2 | AA8: 2 | AB8: 1 | AC8: 2 | AD8: 4 | AE8: 3 | AF8: 4 | AG8: 2 | AH8: 2 | AI8: 2 | AJ8: 2 | AK8: 4 | AL8: 4 | AM8: 3 | AN8: 4 | AO8: 4 | AP8: 2 | AQ8: 2 | AR8: 2 | AS8: 3 | AT8: 5
A9: ID008 | B9: 1 | C9: 1 | D9: 1 | E9: 1 | F9: 1 | G9: 1 | H9: 1 | I9: 1 | J9: 1 | K9: 1 | L9: 1 | M9: 1 | N9: 1 | O9: 3 | P9: 3 | Q9: 3 | R9: 4 | S9: 4 | T9: 4 | U9: 4 | V9: 4 | W9: 4 | X9: 4 | Y9: 2 | Z9: 2 | AA9: 2 | AB9: 1 | AC9: 1 | AD9: 3 | AE9: 3 | AF9: 4 | AG9: 2 | AH9: 2 | AI9: 2 | AJ9: 2 | AK9: 2 | AL9: 3 | AM9: 2 | AN9: 3 | AO9: 3 | AP9: 2 | AQ9: 2 | AR9: 2 | AS9: 3 | AT9: 5
A10: ID009 | B10: 1 | C10: 1 | D10: 1 | E10: 1 | F10: 1 | G10: 1 | H10: 1 | I10: 1 | J10: 1 | K10: 1 | L10: 1 | M10: 1 | N10: 1 | O10: 4 | P10: 4 | Q10: 4 | R10: 4 | S10: 4 | T10: 4 | U10: 4 | V10: 4 | W10: 4 | X10: 4 | Y10: 2 | Z10: 2 | AA10: 2 | AB10: 1 | AC10: 2 | AD10: 4 | AE10: 3 | AF10: 4 | AG10: 2 | AH10: 2 | AI10: 2 | AJ10: 2 | AK10: 2 | AL10: 4 | AM10: 3 | AN10: 4 | AO10: 4 | AP10: 2 | AQ10: 2 | AR10: 2 | AS10: 3 | AT10: 5
A11: ID010 | B11: 1 | C11: 1 | D11: 1 | E11: 1 | F11: 1 | G11: 1 | H11: 1 | I11: 1 | J11: 1 | K11: 1 | L11: 1 | M11: 1 | N11: 1 | O11: 4 | P11: 4 | Q11: 4 | R11: 4 | S11: 4 | T11: 4 | U11: 4 | V11: 4 | W11: 4 | X11: 4 | Y11: 2 | Z11: 2 | AA11: 2 | AB11: 1 | AC11: 1 | AD11: 3 | AE11: 3 | AF11: 4 | AG11: 2 | AH11: 2 | AI11: 2 | AJ11: 2 | AK11: 2 | AL11: 3 | AM11: 2 | AN11: 3 | AO11: 3 | AP11: 2 | AQ11: 2 | AR11: 2 | AS11: 3 | AT11: 5
A12: ID011 | B12: 2 | C12: 4 | D12: 4 | E12: 1 | F12: 1 | G12: 5 | H12: 1 | I12: 4 | J12: 5 | K12: 3 | L12: 2 | M12: 5 | N12: 2 | O12: 1 | P12: 1 | Q12: 1 | R12: 1 | S12: 5 | T12: 2 | U12: 3 | V12: 4 | W12: 3 | X12: 2 | Y12: 2 | Z12: 1 | AA12: 2 | AB12: 1 | AC12: 5 | AD12: 1 | AE12: 1 | AF12: 1 | AG12: 1 | AH12: 1 | AI12: 1 | AJ12: 3 | AK12: 3 | AL12: 4 | AM12: 4 | AN12: 4 | AO12: 1 | AP12: 1 | AQ12: 1 | AR12: 1 | AS12: 3 | AT12: 4
A13: ID012 | B13: 2 | C13: 1 | D13: 3 | E13: 4 | F13: 4 | G13: 3 | H13: 3 | I13: 4 | J13: 3 | K13: 4 | L13: 5 | M13: 4 | N13: 3 | O13: 3 | P13: 4 | Q13: 2 | R13: 4 | S13: 4 | T13: 4 | U13: 5 | V13: 3 | W13: 4 | X13: 3 | Y13: 3 | Z13: 3 | AA13: 3 | AB13: 4 | AC13: 4 | AD13: 4 | AE13: 3 | AF13: 4 | AG13: 4 | AH13: 3 | AI13: 3 | AJ13: 4 | AK13: 4 | AL13: 4 | AM13: 4 | AN13: 4 | AO13: 4 | AP13: 2 | AQ13: 2 | AR13: 3 | AS13: 3 | AT13: 5
... A44: ID043 | B44: 4 | C44: 5 | D44: 3 | E44: 4 | F44: 4 | G44: 4 | H44: 5 | I44: 4 | J44: 4 | K44: 4 | L44: 4 | M44: 4 | N44: 4 | O44: 5 | P44: 5 | Q44: 5 | R44: 4 | S44: 5 | T44: 4 | U44: 4 | V44: 4 | W44: 4 | X44: 3 | Y44: 4 | Z44: 3 | AA44: 4 | AB44: 4 | AC44: 4 | AD44: 4 | AE44: 4 | AF44: 4 | AG44: 1 | AH44: 2 | AI44: 3 | AJ44: 4 | AK44: 5 | AL44: 4 | AM44: 5 | AN44: 4 | AO44: 4 | AP44: 3 | AQ44: 3 | AR44: 5 | AS44: 2 | AT44: 4
A45: ID044 | B45: 4 | C45: 5 | D45: 3 | E45: 4 | F45: 4 | G45: 4 | H45: 5 | I45: 4 | J45: 4 | K45: 5 | L45: 4 | M45: 4 | N45: 4 | O45: 5 | P45: 5 | Q45: 5 | R45: 4 | S45: 5 | T45: 4 | U45: 4 | V45: 4 | W45: 4 | X45: 3 | Y45: 4 | Z45: 3 | AA45: 4 | AB45: 3 | AC45: 3 | AD45: 4 | AE45: 4 | AF45: 4 | AH45: 5 | AI45: 4 | AJ45: 3 | AK45: 4 | AL45: 5 | AM45: 4 | AN45: 5 | AO45: 3 | AP45: 2 | AQ45: 2 | AR45: 5 | AS45: 1 | AT45: 4
A46: ID045 | B46: 4 | C46: 5 | D46: 3 | E46: 4 | F46: 4 | G46: 4 | H46: 5 | I46: 4 | J46: 4 | K46: 5 | L46: 4 | M46: 4 | N46: 4 | O46: 5 | P46: 5 | Q46: 5 | R46: 4 | S46: 5 | T46: 4 | U46: 4 | V46: 4 | W46: 4 | X46: 3 | Y46: 4 | Z46: 3 | AA46: 4 | AB46: 3 | AC46: 3 | AD46: 4 | AE46: 4 | AF46: 4 | AG46: 5 | AH46: 4 | AI46: 3 | AJ46: 4 | AK46: 5 | AL46: 4 | AM46: 5 | AN46: 4 | AO46: 4 | AP46: 3 | AQ46: 3 | AR46: 5 | AS46: 1 | AT46: 4
A47: ID046 | B47: 4 | C47: 5 | D47: 3 | E47: 4 | F47: 4 | G47: 4 | H47: 5 | I47: 4 | J47: 4 | K47: 5 | L47: 4 | M47: 4 | N47: 4 | O47: 5 | P47: 5 | Q47: 5 | R47: 4 | S47: 5 | T47: 4 | U47: 4 | V47: 4 | W47: 4 | X47: 3 | Y47: 4 | Z47: 3 | AA47: 4 | AB47: 4 | AC47: 4 | AD47: 5 | AE47: 4 | AF47: 4 | AG47: 5 | AH47: 4 | AI47: 3 | AJ47: 4 | AK47: 5 | AL47: 4 | AM47: 5 | AN47: 4 | AO47: 4 | AP47: 3 | AQ47: 3 | AR47: 5 | AS47: 3 | AT47: 4
A48: ID047 | B48: 4 | C48: 3 | D48: 3 | E48: 3 | F48: 3 | G48: 5 | H48: 5 | I48: 5 | J48: 5 | K48: 5 | L48: 4 | M48: 4 | N48: 4 | O48: 4 | P48: 4 | Q48: 3 | R48: 3 | S48: 3 | T48: 2 | U48: 2 | V48: 4 | W48: 3 | X48: 2 | Y48: 3 | Z48: 4 | AA48: 4 | AB48: 5 | AC48: 5 | AD48: 5 | AE48: 4 | AF48: 4 | AG48: 3 | AH48: 4 | AI48: 4 | AJ48: 5 | AK48: 4 | AL48: 5 | AM48: 3 | AN48: 3 | AO48: 4 | AP48: 3 | AQ48: 2 | AR48: 4 | AS48: 3 | AT48: 4
A49: ID048 | B49: 1 | C49: 1 | D49: 2 | E49: 2 | F49: 2 | G49: 4 | H49: 4 | I49: 3 | J49: 4 | K49: 4 | L49: 5 | M49: 5 | N49: 5 | O49: 5 | P49: 5 | Q49: 5 | R49: 4 | S49: 3 | T49: 4 | U49: 3 | V49: 4 | W49: 4 | X49: 4 | Y49: 3 | Z49: 2 | AA49: 4 | AB49: 5 | AC49: 5 | AD49: 5 | AE49: 3 | AF49: 2 | AG49: 4 | AH49: 5 | AI49: 5 | AJ49: 4 | AK49: 5 | AL49: 5 | AM49: 5 | AN49: 4 | AO49: 5 | AP49: 3 | AQ49: 5 | AR49: 4 | AS49: 1 | AT49: 5
A50: ID049 | B50: 4 | C50: 2 | D50: 4 | E50: 4 | F50: 3 | G50: 4 | H50: 5 | I50: 3 | J50: 5 | K50: 3 | L50: 5 | M50: 5 | N50: 5 | O50: 4 | P50: 4 | Q50: 3 | R50: 2 | S50: 4 | T50: 5 | U50: 4 | V50: 4 | W50: 4 | X50: 4 | Y50: 3 | Z50: 3 | AA50: 4 | AB50: 4 | AC50: 5 | AD50: 5 | AE50: 3 | AF50: 3 | AG50: 4 | AH50: 3 | AI50: 4 | AJ50: 4 | AK50: 3 | AL50: 4 | AM50: 4 | AN50: 4 | AO50: 4 | AP50: 3 | AQ50: 3 | AR50: 3 | AS50: 3 | AT50: 3
A51: ID050 | B51: 5 | C51: 4 | D51: 4 | E51: 5 | F51: 2 | G51: 5 | H51: 5 | I51: 5 | J51: 4 | K51: 4 | L51: 4 | M51: 4 | N51: 5 | O51: 3 | P51: 5 | Q51: 4 | R51: 5 | S51: 4 | T51: 4 | U51: 4 | V51: 4 | W51: 4 | X51: 4 | Y51: 5 | Z51: 4 | AA51: 5 | AB51: 5 | AC51: 4 | AD51: 5 | AE51: 5 | AF51: 4 | AG51: 4 | AH51: 5 | AI51: 4 | AJ51: 4 | AK51: 4 | AL51: 5 | AM51: 4 | AN51: 5 | AO51: 4 | AP51: 4 | AQ51: 4 | AR51: 4 | AS51: 1 | AT51: 4
A52: ID051 | B52: 4 | C52: 2 | D52: 4 | E52: 3 | F52: 3 | G52: 4 | H52: 4 | I52: 3 | J52: 4 | K52: 3 | L52: 3 | M52: 5 | N52: 4 | O52: 2 | P52: 2 | Q52: 3 | R52: 3 | S52: 4 | T52: 3 | U52: 2 | V52: 3 | W52: 4 | X52: 4 | Y52: 3 | Z52: 3 | AA52: 3 | AB52: 2 | AC52: 2 | AD52: 3 | AE52: 4 | AF52: 4 | AG52: 4 | AH52: 3 | AI52: 3 | AJ52: 4 | AK52: 3 | AL52: 4 | AM52: 4 | AN52: 3 | AO52: 4 | AP52: 3 | AQ52: 3 | AR52: 2 | AS52: 3 | AT52: 4
A53: ID052 | B53: 5 | C53: 4 | D53: 4 | E53: 5 | F53: 2 | G53: 5 | H53: 5 | I53: 5 | J53: 4 | K53: 4 | L53: 4 | M53: 4 | N53: 5 | O53: 4 | P53: 5 | Q53: 4 | R53: 5 | S53: 4 | T53: 4 | U53: 4 | V53: 4 | W53: 4 | X53: 4 | Y53: 5 | Z53: 4 | AA53: 5 | AB53: 5 | AC53: 4 | AD53: 5 | AE53: 5 | AF53: 4 | AG53: 4 | AH53: 5 | AI53: 4 | AJ53: 4 | AK53: 4 | AL53: 4 | AM53: 5 | AN53: 4 | AO53: 5 | AP53: 4 | AQ53: 4 | AR53: 4 | AS53: 3 | AT53: 3
A54: ID053 | B54: 5 | C54: 4 | D54: 1 | E54: 3 | F54: 1 | G54: 4 | H54: 4 | I54: 4 | J54: 4 | K54: 4 | L54: 4 | M54: 3 | N54: 3 | O54: 3 | P54: 3 | Q54: 2 | R54: 4 | S54: 3 | T54: 3 | U54: 1 | V54: 2 | W54: 3 | X54: 4 | Y54: 3 | Z54: 2 | AA54: 3 | AB54: 3 | AC54: 4 | AD54: 5 | AE54: 1 | AF54: 2 | AG54: 3 | AH54: 2 | AI54: 3 | AJ54: 5 | AK54: 4 | AL54: 2 | AM54: 3 | AN54: 3 | AO54: 3 | AP54: 2 | AQ54: 2 | AR54: 4 | AS54: 3 | AT54: 5
A55: ID054 | B55: 4 | C55: 5 | D55: 3 | E55: 4 | F55: 4 | G55: 4 | H55: 5 | I55: 4 | J55: 4 | K55: 5 | L55: 4 | M55: 4 | N55: 4 | O55: 5 | P55: 5 | Q55: 5 | R55: 4 | S55: 5 | T55: 4 | U55: 4 | V55: 4 | W55: 4 | X55: 3 | Y55: 4 | Z55: 3 | AA55: 4 | AB55: 4 | AC55: 4 | AD55: 5 | AE55: 4 | AF55: 4 | AG55: 5 | AH55: 4 | AI55: 3 | AJ55: 4 | AK55: 5 | AL55: 4 | AM55: 5 | AN55: 4 | AO55: 4 | AP55: 3 | AQ55: 3 | AR55: 5 | AS55: 3 | AT55: 4
A56: ID055 | B56: 2 | C56: 3 | D56: 4 | E56: 2 | F56: 4 | G56: 3 | H56: 2 | I56: 3 | J56: 4 | K56: 3 | L56: 4 | M56: 5 | N56: 5 | O56: 3 | P56: 5 | Q56: 4 | R56: 5 | S56: 5 | T56: 4 | U56: 5 | V56: 3 | W56: 5 | X56: 5 | Y56: 3 | Z56: 4 | AA56: 4 | AB56: 3 | AC56: 3 | AD56: 4 | AE56: 3 | AF56: 3 | AG56: 3 | AH56: 4 | AI56: 3 | AJ56: 4 | AK56: 4 | AL56: 4 | AM56: 5 | AN56: 4 | AO56: 4 | AP56: 3 | AQ56: 3 | AR56: 3 | AS56: 3 | AT56: 5
A57: ID056 | B57: 1 | C57: 1 | D57: 1 | E57: 1 | F57: 1 | G57: 5 | H57: 5 | I57: 3 | J57: 2 | K57: 5 | L57: 5 | M57: 5 | N57: 4 | O57: 5 | P57: 5 | Q57: 5 | R57: 5 | S57: 5 | T57: 4 | U57: 4 | V57: 3 | W57: 1 | X57: 1 | Y57: 2 | Z57: 2 | AA57: 5 | AB57: 5 | AC57: 5 | AD57: 5 | AE57: 2 | AF57: 2 | AG57: 3 | AH57: 5 | AI57: 4 | AJ57: 5 | AK57: 3 | AL57: 4 | AM57: 5 | AN57: 4 | AO57: 5 | AP57: 2 | AQ57: 1 | AR57: 5 | AS57: 1 | AT57: 5
... A72: ID071 | B72: 4 | C72: 4 | D72: 3 | E72: 4 | F72: 4 | G72: 4 | H72: 4 | I72: 4 | J72: 4 | K72: 4 | L72: 4 | M72: 4 | N72: 4 | O72: 4 | P72: 4 | Q72: 4 | R72: 4 | S72: 4 | T72: 4 | U72: 4 | V72: 4 | W72: 4 | X72: 3 | Y72: 3 | Z72: 3 | AA72: 4 | AB72: 5 | AC72: 4 | AD72: 5 | AE72: 3 | AF72: 4 | AG72: 4 | AH72: 5 | AI72: 4 | AJ72: 4 | AK72: 4 | AL72: 4 | AM72: 4 | AN72: 5 | AO72: 5 | AP72: 4 | AQ72: 4 | AR72: 5 | AS72: 1 | AT72: 5
A73: ID072 | B73: 3 | C73: 3 | D73: 3 | E73: 3 | F73: 3 | G73: 3 | H73: 2 | I73: 3 | J73: 2 | K73: 3 | L73: 3 | M73: 3 | N73: 4 | O73: 4 | P73: 4 | Q73: 4 | R73: 5 | T73: 2 | U73: 2 | V73: 3 | W73: 3 | X73: 2 | Y73: 3 | Z73: 3 | AA73: 4 | AB73: 3 | AC73: 3 | AD73: 4 | AE73: 3 | AF73: 3 | AG73: 3 | AH73: 2 | AI73: 2 | AJ73: 4 | AK73: 5 | AL73: 4 | AM73: 5 | AN73: 5 | AO73: 2 | AP73: 2 | AQ73: 2 | AR73: 4 | AS73: 3 | AT73: 5
A74: ID073 | B74: 1 | C74: 1 | D74: 5 | E74: 1 | F74: 1 | G74: 5 | H74: 5 | I74: 5 | J74: 5 | K74: 5 | L74: 5 | M74: 5 | N74: 5 | O74: 4 | P74: 4 | Q74: 4 | R74: 4 | S74: 5 | T74: 5 | U74: 5 | V74: 5 | W74: 5 | X74: 5 | Y74: 5 | Z74: 3 | AA74: 3 | AB74: 3 | AC74: 5 | AD74: 5 | AE74: 3 | AF74: 3 | AG74: 1 | AH74: 1 | AI74: 1 | AJ74: 1 | AK74: 1 | AL74: 5 | AM74: 5 | AN74: 5 | AO74: 5 | AP74: 1 | AQ74: 1 | AR74: 1 | AS74: 3 | AT74: 4
A75: ID074 | B75: 4 | C75: 4 | D75: 1 | E75: 3 | F75: 3 | G75: 4 | H75: 4 | I75: 5 | J75: 4 | K75: 5 | L75: 3 | M75: 5 | N75: 5 | O75: 3 | P75: 5 | Q75: 3 | R75: 4 | S75: 5 | T75: 5 | U75: 4 | V75: 5 | W75: 4 | X75: 3 | Y75: 5 | Z75: 3 | AA75: 5 | AB75: 3 | AC75: 4 | AD75: 4 | AE75: 3 | AF75: 4 | AG75: 5 | AH75: 5 | AI75: 5 | AJ75: 3 | AK75: 2 | AL75: 5 | AM75: 5 | AN75: 5 | AO75: 4 | AP75: 3 | AQ75: 3 | AR75: 4 | AS75: 1 | AT75: 4
A76: ID075 | B76: 4 | C76: 4 | D76: 1 | E76: 3 | F76: 3 | G76: 4 | H76: 4 | I76: 3 | J76: 4 | K76: 5 | L76: 3 | M76: 5 | N76: 5 | O76: 3 | P76: 4 | Q76: 2 | R76: 4 | S76: 3 | T76: 3 | U76: 4 | V76: 5 | W76: 4 | X76: 3 | Y76: 5 | Z76: 3 | AA76: 5 | AB76: 4 | AC76: 4 | AD76: 4 | AE76: 4 | AF76: 5 | AG76: 2 | AH76: 2 | AI76: 2 | AJ76: 5 | AK76: 3 | AL76: 4 | AM76: 4 | AN76: 4 | AO76: 4 | AP76: 3 | AQ76: 3 | AR76: 4 | AS76: 3 | AT76: 4
A77: ID076 | B77: 3 | C77: 1 | D77: 1 | E77: 2 | F77: 1 | G77: 1 | H77: 1 | I77: 3 | J77: 1 | K77: 5 | L77: 1 | M77: 3 | N77: 1 | O77: 5 | P77: 4 | Q77: 2 | R77: 5 | S77: 1 | T77: 1 | U77: 3 | V77: 5 | W77: 3 | X77: 3 | Y77: 2 | Z77: 3 | AA77: 3 | AB77: 5 | AC77: 5 | AD77: 5 | AE77: 5 | AF77: 2 | AG77: 5 | AH77: 2 | AI77: 2 | AJ77: 1 | AK77: 4 | AL77: 5 | AM77: 5 | AN77: 5 | AO77: 1 | AP77: 2 | AQ77: 2 | AR77: 5 | AS77: 1 | AT77: 3
A78: ID077 | B78: 5 | C78: 3 | D78: 3 | E78: 3 | F78: 2 | G78: 5 | H78: 4 | I78: 4 | J78: 4 | K78: 4 | L78: 4 | M78: 5 | N78: 4 | O78: 3 | P78: 3 | Q78: 2 | R78: 3 | S78: 5 | T78: 5 | U78: 5 | V78: 5 | W78: 5 | X78: 5 | Y78: 5 | Z78: 4 | AA78: 5 | AB78: 4 | AC78: 4 | AD78: 5 | AE78: 5 | AF78: 4 | AG78: 5 | AH78: 5 | AI78: 5 | AJ78: 5 | AK78: 4 | AL78: 5 | AM78: 5 | AN78: 5 | AO78: 5 | AP78: 3 | AQ78: 3 | AR78: 4 | AS78: 2 | AT78: 3
A79: ID078 | B79: 5 | C79: 3 | D79: 2 | E79: 3 | F79: 5 | G79: 3 | H79: 3 | I79: 3 | J79: 4 | K79: 4 | L79: 5 | M79: 4 | N79: 5 | O79: 4 | P79: 3 | Q79: 3 | R79: 3 | S79: 5 | T79: 5 | U79: 5 | V79: 4 | W79: 5 | X79: 5 | Y79: 4 | Z79: 4 | AA79: 4 | AB79: 4 | AC79: 4 | AD79: 5 | AE79: 4 | AF79: 3 | AG79: 3 | AH79: 3 | AI79: 5 | AJ79: 5 | AK79: 5 | AL79: 4 | AM79: 4 | AN79: 4 | AO79: 5 | AP79: 3 | AQ79: 3 | AR79: 5 | AS79: 2 | AT79: 5
A80: ID079 | B80: 2 | C80: 2 | D80: 2 | E80: 2 | F80: 1 | G80: 3 | H80: 3 | I80: 1 | J80: 1 | K80: 1 | L80: 1 | M80: 2 | N80: 3 | O80: 3 | P80: 3 | Q80: 1 | R80: 3 | S80: 2 | T80: 1 | U80: 2 | V80: 3 | W80: 3 | X80: 4 | Y80: 2 | Z80: 1 | AA80: 2 | AB80: 1 | AC80: 3 | AD80: 4 | AE80: 2 | AF80: 1 | AG80: 2 | AH80: 1 | AI80: 2 | AJ80: 3 | AK80: 3 | AL80: 5 | AM80: 5 | AN80: 4 | AO80: 4 | AP80: 1 | AQ80: 2 | AR80: 3 | AS80: 1 | AT80: 5
A81: ID080 | B81: 3 | C81: 4 | D81: 2 | E81: 2 | F81: 3 | G81: 4 | H81: 4 | I81: 4 | J81: 5 | K81: 3 | L81: 5 | M81: 4 | N81: 5 | O81: 5 | P81: 5 | Q81: 3 | R81: 2 | S81: 4 | T81: 4 | U81: 4 | V81: 4 | W81: 4 | X81: 3 | Y81: 4 | Z81: 3 | AA81: 4 | AB81: 5 | AC81: 5 | AD81: 5 | AE81: 4 | AF81: 3 | AG81: 3 | AH81: 3 | AI81: 3 | AJ81: 3 | AK81: 3 | AL81: 3 | AM81: 4 | AN81: 5 | AO81: 3 | AP81: 2 | AQ81: 3 | AR81: 4 | AS81: 1 | AT81: 5
A82: ID081 | B82: 2 | C82: 2 | D82: 3 | E82: 4 | F82: 5 | G82: 5 | H82: 5 | I82: 4 | J82: 5 | K82: 5 | L82: 4 | M82: 4 | N82: 5 | O82: 4 | P82: 4 | Q82: 4 | R82: 4 | S82: 3 | T82: 4 | U82: 4 | V82: 2 | W82: 4 | X82: 4 | Y82: 4 | Z82: 4 | AA82: 5 | AB82: 5 | AC82: 5 | AD82: 4 | AE82: 5 | AF82: 5 | AG82: 5 | AH82: 4 | AI82: 4 | AJ82: 4 | AK82: 4 | AL82: 5 | AM82: 5 | AN82: 4 | AO82: 4 | AP82: 2 | AQ82: 2 | AR82: 3 | AS82: 1 | AT82: 5
A83: ID082 | B83: 4 | C83: 1 | D83: 2 | E83: 3 | F83: 4 | G83: 5 | H83: 5 | I83: 5 | J83: 3 | K83: 3 | L83: 4 | M83: 5 | N83: 5 | O83: 4 | P83: 1 | Q83: 1 | R83: 1 | S83: 5 | T83: 4 | U83: 5 | V83: 3 | W83: 1 | X83: 1 | Y83: 3 | Z83: 2 | AA83: 3 | AB83: 4 | AC83: 4 | AD83: 4 | AE83: 4 | AF83: 4 | AG83: 4 | AH83: 3 | AI83: 2 | AJ83: 1 | AK83: 1 | AL83: 5 | AM83: 5 | AN83: 5 | AO83: 2 | AP83: 1 | AQ83: 1 | AR83: 3 | AS83: 1 | AT83: 5
A84: ID083 | B84: 4 | C84: 5 | D84: 3 | E84: 4 | F84: 4 | G84: 4 | H84: 4 | I84: 4 | J84: 4 | K84: 4 | L84: 4 | M84: 4 | N84: 4 | O84: 5 | P84: 5 | Q84: 5 | R84: 5 | S84: 5 | T84: 5 | U84: 4 | V84: 4 | W84: 5 | X84: 4 | Y84: 5 | Z84: 3 | AA84: 4 | AB84: 4 | AC84: 4 | AD84: 4 | AE84: 5 | AF84: 5 | AG84: 4 | AH84: 4 | AI84: 3 | AJ84: 4 | AK84: 5 | AL84: 4 | AM84: 4 | AN84: 4 | AO84: 2 | AP84: 4 | AQ84: 3 | AR84: 3 | AS84: 3 | AT84: 5
...

Sheet 3rd iteration
A1: Factor Analysis - Principal Component Extraction
B5: 1.Delay in delivering material to construction site | C5: 2.Monopoly of material by some suppliers | D5: 3.Prices fluctuation | E5: 4.Types of material availability at local market | F5: 5.Lack of consultant’s knowledge of available materials | G5: 6.Low productivity | H5: 7.Poor work execution | I5: 8.Shortage of laborers | J5: 9.Mistakes happens during construction phase | K5: 10.Unavailability of equipment | L5: 11.Lack of engineering experience | M5: 12.Construction cost underestimation | N5: 13.Poor site management | O5: 14.Delayed payment for completed work | P5: 15.Cash flow problem during construction | Q5: 16.High rate of interest | R5: 17.Contractor’s financial difficulties | S5: 19.Change design | T5: 20.Errors and omission in design | U5: 21.Incomplete design drawings and specifications at tendering stage | V5: 22.Delay in preparation and approval of drawing | W5: 23.Inaccurate quantity take-off | X5: 24.Long period from planning of project to construction | Y5: 25.Delays in issuing information to the contractor during construction stage | Z5: 26.No practical use of earned value management system | AA5: 27.Lack of cost planning/monitoring during pre and post contract stage | AB5: 28.Poor communication between client, consultant and contractor | AC5: 29.Insufficient coordination between local authority who is responsible about road projects and service authorities | AD5: 30.Delays in decisions making by the approval authorities | AE5: 31.Change schedule | AF5: 32.Stoppages because of work being rejected by consultant | AG5: 33.Lowest bid price | AH5: 34.Insufficient time for preparation of contract documents | AI5: 35.Discrepancies in contract documents | AJ5: 36.Underestimation of time for completion of project | AK5: 37.Extension of time with cost claims | AL5: 38.Scope and specification changes | AM5: 39.Changes in client requirements | AN5: 40.Frequency of variation orders and additional works | AO5: 41.Rework due to error in execution | AP5: 42.Weather conditions | AQ5: 43.Accidents during construction | AR5: 44.Delay in getting NOCs from different government authorities | AS5: Location of organization | AT5: Relevant working experience
A6: Mean | B6: 3.08 | C6: 2.99 | D6: 2.74 | E6: 2.92 | F6: 2.83 | G6: 3.45 | H6: 3.53 | I6: 3.41 | J6: 3.33 | K6: 3.42 | L6: 3.51 | M6: 3.79 | N6: 3.77 | O6: 3.61 | P6: 3.63 | Q6: 3.17 | R6: 3.58 | S6: 3.81 | T6: 3.47 | U6: 3.52 | V6: 3.62 | W6: 3.64 | X6: 3.48 | Y6: 3.25 | Z6: 3.06 | AA6: 3.46 | AB6: 3.32 | AC6: 3.55 | AD6: 4.03 | AE6: 3.28 | AF6: 3.1 | AG6: 3.28 | AH6: 3.18 | AI6: 3.19 | AJ6: 3.66 | AK6: 3.65 | AL6: 3.94 | AM6: 4.07 | AN6: 3.91 | AO6: 3.56 | AP6: 2.49 | AQ6: 2.7 | AR6: 3.66 | AS6: 2.15 | AT6: 4.05
A7: Std dev | B7: 1.261996 | C7: 1.334781 | D7: 1.117803 | E7: 1.058144 | F7: 1.255893 | G7: 1.092402 | H7: 1.191544 | I7: 1.114803 | J7: 1.208982 | K7: 1.171328 | L7: 1.18004 | M7: 1.203593 | N7: 1.220092 | O7: 0.993181 | P7: 1.123866 | Q7: 1.227536 | R7: 1.1653 | S7: 1.00634 | T7: 1.143285 | U7: 1.073714 | V7: 0.991543 | W7: 0.996794 | X7: 0.998965 | Y7: 1.010289 | Z7: 0.984215 | AA7: 0.976983 | AB7: 1.236769 | AC7: 1.066304 | AD7: 0.934051 | AE7: 1.030558 | AF7: 1.09874 | AG7: 1.22252 | AH7: 1.142251 | AI7: 1.047808 | AJ7: 0.992536 | AK7: 0.994766 | AL7: 0.902081 | AM7: 0.954237 | AN7: 0.910882 | AO7: 1.03884 | AP7: 1.026872 | AQ7: 1.132335 | AR7: 1.100218 | AS7: 0.824858 | AT7: 1.121673
A8: Skewness | B8: -0.35981 | C8: 0.012937 | D8: -0.17796 | E8: -0.19224 | F8: -0.08853 | G8: -0.72048 | H8: -0.77222 | I8: -0.60971 | J8: -0.5607 | K8: -0.55018 | L8: -0.76867 | M8: -0.84061 | N8: -0.96303 | O8: -0.41448 | P8: -0.70587 | Q8: -0.23326 | R8: -0.72541 | S8: -0.72531 | T8: -0.56682 | U8: -0.46137 | V8: -0.45528 | W8: -0.64329 | X8: -0.18765 | Y8: -0.15061 | Z8: -0.1132 | AA8: -0.44213 | AB8: -0.47709 | AC8: -0.45599 | AD8: -0.79229 | AE8: -0.35032 | AF8: -0.30751 | AG8: -0.2018 | AH8: -0.04753 | AI8: -0.0886 | AJ8: -0.72844 | AK8: -0.55498 | AL8: -0.82294 | AM8: -0.733 | AN8: -0.4986 | AO8: -0.52387 | AP8: 0.285851 | AQ8: 0.497504 | AR8: -0.68377 | AS8: -0.29413 | AT8: -1.25133
A9: Kurtosis | B9: -1.08886 | C9: -1.14576 | D9: -0.71607 | E9: -0.40074 | F9: -1.02825 | G9: -0.18631 | H9: -0.2154 | I9: -0.10683 | J9: -0.57079 | K9: -0.34221 | L9: -0.19563 | M9: -0.13374 | N9: 0.028493 | O9: -0.15998 | P9: -0.20726 | Q9: -0.86994 | R9: -0.3229 | S9: 0.025995 | T9: -0.55378 | U9: -0.5538 | V9: -0.48209 | W9: 0.327286 | X9: -0.52799 | Y9: -0.43982 | Z9: -0.09886 | AA9: -0.28377 | AB9: -0.70887 | AC9: -0.47317 | AD9: 0.308968 | AE9: -0.36556 | AF9: -0.73755 | AG9: -0.92286 | AH9: -0.87091 | AI9: -0.75921 | AJ9: 0.279245 | AK9: -0.05006 | AL9: 0.384649 | AM9: -0.44941 | AN9: -0.26897 | AO9: -0.13618 | AP9: -0.4768 | AQ9: -0.48746 | AR9: -0.14256 | AS9: -1.47084 | AT9: 0.986304
A11: Correlation Matrix
B13: 1.Delay in delivering material to construction site | C13: 2.Monopoly of material by some suppliers | D13: 3.Prices fluctuation | E13: 4.Types of material availability at local market | F13: 5.Lack of consultant’s knowledge of available materials | G13: 6.Low productivity | H13: 7.Poor work execution | I13: 8.Shortage of laborers | J13: 9.Mistakes happens during construction phase | K13: 10.Unavailability of equipment | L13: 11.Lack of engineering experience | M13: 12.Construction cost underestimation | N13: 13.Poor site management | O13: 14.Delayed payment for completed work | P13: 15.Cash flow problem during construction | Q13: 16.High rate of interest | R13: 17.Contractor’s financial difficulties | S13: 19.Change design | T13: 20.Errors and omission in design | U13: 21.Incomplete design drawings and specifications at tendering stage | V13: 22.Delay in preparation and approval of drawing | W13: 23.Inaccurate quantity take-off | X13: 24.Long period from planning of project to construction | Y13: 25.Delays in issuing information to the contractor during construction stage | Z13: 26.No practical use of earned value management system | AA13: 27.Lack of cost planning/monitoring during pre and post contract stage | AB13: 28.Poor communication between client, consultant and contractor | AC13: 29.Insufficient coordination between local authority who is responsible about road projects and service authorities | AD13: 30.Delays in decisions making by the approval authorities | AE13: 31.Change schedule | AF13: 32.Stoppages because of work being rejected by consultant | AG13: 33.Lowest bid price | AH13: 34.Insufficient time for preparation of contract documents | AI13: 35.Discrepancies in contract documents | AJ13: 36.Underestimation of time for completion of project | AK13: 37.Extension of time with cost claims | AL13: 38.Scope and specification changes | AM13: 39.Changes in client requirements | AN13: 40.Frequency of variation orders and additional works | AO13: 41.Rework due to error in execution | AP13: 42.Weather conditions | AQ13: 43.Accidents during construction | AR13: 44.Delay in getting NOCs from different government authorities | AS13: Location of organization | AT13: Relevant working experience
A14: 1.Delay in delivering material to construction site | B14: 1 | C14: 0.617447 | D14: 0.213695 | E14: 0.673332 | F14: 0.374378 | G14: 0.484591 | H14: 0.538329 | I14: 0.547602 | J14: 0.402341 | K14: 0.470701 | L14: 0.436309 | M14: 0.308012 | N14: 0.276926 | O14: 0.125762 | P14: 0.184925 | Q14: 0.058699 | R14: 0.086557 | S14: 0.15312 | T14: 0.074863 | U14: 0.029097 | V14: 0.088645 | W14: -0.13842 | X14: -0.07117 | Y14: 0.263414 | Z14: 0.150097 | AA14: 0.273813 | AB14: 0.324388 | AC14: 0.186236 | AD14: 0.106013 | AE14: 0.022708 | AF14: 0.367218 | AG14: 0.400073 | AH14: 0.240698 | AI14: 0.287874 | AJ14: 0.313114 | AK14: 0.323179 | AL14: 0.103723 | AM14: 0.181608 | AN14: 0.159553 | AO14: 0.261497 | AP14: 0.344058 | AQ14: 0.42143 | AR14: 0.340472 | AS14: -0.065 | AT14: -0.15217
A15: 2.Monopoly of material by some suppliers | B15: 0.617447 | C15: 1 | D15: 0.334336 | E15: 0.558668 | F15: 0.426873 | G15: 0.343882 | H15: 0.384931 | I15: 0.393506 | J15: 0.314199 | K15: 0.362904 | L15: 0.427641 | M15: 0.197617 | N15: 0.297861 | O15: 0.101421 | P15: 0.199332 | Q15: 0.146866 | R15: 0.147563 | S15: 0.303899 | T15: 0.221947 | U15: 0.044296 | V15: -0.04365 | W15: 0.015877 | X15: -0.05185 | Y15: 0.231034 | Z15: -0.0423 | AA15: 0.209817 | AB15: 0.180847 | AC15: 0.073655 | AD15: -0.1077 | AE15: -0.07324 | AF15: 0.307204 | AG15: 0.300923 | AH15: 0.17474 | AI15: 0.148534 | AJ15: 0.322445 | AK15: 0.317957 | AL15: -0.13152 | AM15: 0.10813 | AN15: 0.033642 | AO15: 0.179366 | AP15: 0.335591 | AQ15: 0.421812 | AR15: 0.350091 | AS15: 0.154389 | AT15: -0.18119
A16: 3.Prices fluctuation | B16: 0.213695 | C16: 0.334336 | D16: 1 | E16: 0.511606 | F16: 0.39448 | G16: 0.34846 | H16: 0.413956 | I16: 0.279592 | J16: 0.400803 | K16: 0.230993 | L16: 0.382316 | M16: 0.358718 | N16: 0.36283 | O16: -0.0595 | P16: 0.002948 | Q16: 0.061672 | R16: 0.004653 | S16: 0.265123 | T16: 0.089193 | U16: 0.131057 | V16: 0.023002 | W16: 0.045399 | X16: 0.108239 | Y16: 0.039962 | Z16: 0.25724 | AA16: 0.18405 | AB16: 0.180387 | AC16: 0.076737 | AD16: -0.11429 | AE16: 0.051891 | AF16: 0.14818 | AG16: 0.174717 | AH16: 0.110398 | AI16: 0.061732 | AJ16: 0.251131 | AK16: 0.088153 | AL16: 0.144634 | AM16: 0.205128 | AN16: -0.0201 | AO16: 0.223326 | AP16: 0.109573 | AQ16: 0.178412 | AR16: -0.00079 | AS16: 0.235288 | AT16: -0.25457
A17: 4.Types of material availability at local market | B17: 0.673332 | C17: 0.558668 | D17: 0.511606 | E17: 1 | F17: 0.55855 | G17: 0.527909 | H17: 0.625926 | I17: 0.531127 | J17: 0.392543 | K17: 0.462761 | L17: 0.515672 | M17: 0.360599 | N17: 0.448709 | O17: 0.099347 | P17: 0.17308 | Q17: 0.147487 | R17: 0.134703 | S17: 0.212299 | T17: 0.153376 | U17: 0.110675 | V17: 0.035865 | W17: 0.063933 | X17: -0.02161 | Y17: 0.30702 | Z17: 0.269866 | AA17: 0.390218 | AB17: 0.374996 | AC17: 0.146989 | AD17: 0.160056 | AE17: 0.153899 | AF17: 0.404253 | AG17: 0.415851 | AH17: 0.303602 | AI17: 0.278869 | AJ17: 0.341506 | AK17: 0.248039 | AL17: 0.120219 | AM17: 0.231206 | AN17: 0.024896 | AO17: 0.312467 | AP17: 0.389342 | AQ17: 0.430293 | AR17: 0.222421 | AS17: 0.05624 | AT17: -0.15982
A18: 5.Lack of consultant’s knowledge of available materials | B18: 0.374378 | C18: 0.426873 | D18: 0.39448 | E18: 0.55855 | F18: 1 | G18: 0.426822 | H18: 0.516328 | I18: 0.421754 | J18: 0.550363 | K18: 0.394762 | L18: 0.497702 | M18: 0.490624 | N18: 0.553822 | O18: 0.163971 | P18: 0.177539 | Q18: 0.433905 | R18: 0.051387 | S18: 0.467038 | T18: 0.437446 | U18: 0.410275 | V18: 0.285149 | W18: 0.348235 | X18: 0.042098 | Y18: 0.426336 | Z18: 0.454197 | AA18: 0.45199 | AB18: 0.434222 | AC18: 0.228668 | AD18: 0.088695 | AE18: 0.235763 | AF18: 0.500686 | AG18: 0.357036 | AH18: 0.414392 | AI18: 0.402695 | AJ18: 0.2871 | AK18: 0.274633 | AL18: 0.227963 | AM18: 0.335344 | AN18: 0.188694 | AO18: 0.315329 | AP18: 0.410886 | AQ18: 0.380858 | AR18: 0.2323 | AS18: 0.03796 | AT18: -0.18844
A19: 6.Low productivity | B19: 0.484591 | C19: 0.343882 | D19: 0.34846 | E19: 0.527909 | F19: 0.426822 | G19: 1 | H19: 0.82122 | I19: 0.724846 | J19: 0.702263 | K19: 0.546242 | L19: 0.65229 | M19: 0.660151 | N19: 0.675342 | O19: 0.08175 | P19: 0.098779 | Q19: 0.233492 | R19: 0.043609 | S19: 0.373471 | T19: 0.18297 | U19: 0.094957 | V19: 0.099699 | W19: 0.07354 | X19: -0.05932 | Y19: 0.403001 | Z19: 0.258229 | AA19: 0.444134 | AB19: 0.370043 | AC19: 0.382941 | AD19: 0.111805 | AE19: 0.093861 | AF19: 0.327582 | AG19: 0.161801 | AH19: 0.359979 | AI19: 0.366204 | AJ19: 0.456326 | AK19: 0.167462 | AL19: 0.203022 | AM19: 0.242078 | AN19: 0.170312 | AO19: 0.374298 | AP19: 0.281705 | AQ19: 0.233685 | AR19: 0.217358 | AS19: -0.1268 | AT19: 0.093833
A20: 7.Poor work execution | B20: 0.538329 | C20: 0.384931 | D20: 0.413956 | E20: 0.625926 | F20: 0.516328 | G20: 0.82122 | H20: 1 | I20: 0.606889 | J20: 0.681291 | K20: 0.54631 | L20: 0.67464 | M20: 0.594184 | N20: 0.692462 | O20: 0.199402 | P20: 0.18836 | Q20: 0.266013 | R20: 0.134551 | S20: 0.424654 | T20: 0.231783 | U20: 0.154811 | V20: 0.187002 | W20: 0.086875 | X20: 0.029888 | Y20: 0.424424 | Z20: 0.324708 | AA20: 0.536029 | AB20: 0.458468 | AC20: 0.36675 | AD20: 0.265599 | AE20: 0.112323 | AF20: 0.428292 | AG20: 0.327125 | AH20: 0.38895 | AI20: 0.463202 | AJ20: 0.483567 | AK20: 0.192141 | AL20: 0.231245 | AM20: 0.346915 | AN20: 0.166011 | AO20: 0.482768 | AP20: 0.306286 | AQ20: 0.300448 | AR20: 0.332622 | AS20: -0.08863 | AT20: -0.02331
A21: 8.Shortage of laborers | B21: 0.547602 | C21: 0.393506 | D21: 0.279592 | E21: 0.531127 | F21: 0.421754 | G21: 0.724846 | H21: 0.606889 | I21: 1 | J21: 0.637295 | K21: 0.692857 | L21: 0.610079 | M21: 0.660787 | N21: 0.543651 | O21: 0.24175 | P21: 0.160673 | Q21: 0.254432 | R21: 0.074707 | S21: 0.343841 | T21: 0.20507 | U21: 0.092432 | V21: 0.119919 | W21: -0.05228 | X21: -0.0863 | Y21: 0.355575 | Z21: 0.332783 | AA21: 0.318246 | AB21: 0.435951 | AC21: 0.309141 | AD21: 0.15158 | AE21: 0.264405 | AF21: 0.290272 | AG21: 0.314764 | AH21: 0.428882 | AI21: 0.331026 | AJ21: 0.245979 | AK21: 0.198476 | AL21: 0.259149 | AM21: 0.272815 | AN21: 0.196012 | AO21: 0.19772 | AP21: 0.359866 | AQ21: 0.31944 | AR21: 0.331813 | AS21: -0.12448 | AT21: 0.058905
A22: 9.Mistakes happens during construction phase | B22: 0.402341 | C22: 0.314199 | D22: 0.400803 | E22: 0.392543 | F22: 0.550363 | G22: 0.702263 | H22: 0.681291 | I22: 0.637295 | J22: 1 | K22: 0.602859 | L22: 0.640484 | M22: 0.716775 | N22: 0.57909 | O22: -0.06243 | P22: 0.05619 | Q22: 0.30667 | R22: -0.10843 | S22: 0.463957 | T22: 0.354787 | U22: 0.182947 | V22: 0.175382 | W22: 0.260035 | X22: 0.04027 | Y22: 0.337708 | Z22: 0.380576 | AA22: 0.475915 | AB22: 0.486931 | AC22: 0.362106 | AD22: 0.041629 | AE22: 0.166739 | AF22: 0.389531 | AG22: 0.217027 | AH22: 0.38808 | AI22: 0.440433 | AJ22: 0.510131 | AK22: 0.101647 | AL22: 0.173653 | AM22: 0.276445 | AN22: 0.244472 | AO22: 0.358397 | AP22: 0.346162 | AQ22: 0.320782 | AR22: 0.107286 | AS22: -0.03594 | AT22: -0.10373
A23: 10.Unavailability of equipment | B23: 0.470701 | C23: 0.362904 | D23: 0.230993 | E23: 0.462761 | F23: 0.394762 | G23: 0.546242 | H23: 0.54631 | I23: 0.692857 | J23: 0.602859 | K23: 1 | L23: 0.534699 | M23: 0.592702 | N23: 0.392132 | O23: 0.240034 | P23: 0.362282 | Q23: 0.338058 | R23: 0.334682 | S23: 0.201274 | T23: 0.231534 | U23: 0.19579 | V23: 0.196954 | W23: 0.135718 | X23: -0.09845 | Y23: 0.278545 | Z23: 0.355037 | AA23: 0.526397 | AB23: 0.641276 | AC23: 0.418262 | AD23: 0.066973 | AE23: 0.263137 | AF23: 0.326977 | AG23: 0.329632 | AH23: 0.398407 | AI23: 0.35683 | AJ23: 0.255843 | AK23: 0.242508 | AL23: 0.248417 | AM23: 0.36385 | AN23: 0.263656 | AO23: 0.258042 | AP23: 0.394698 | AQ23: 0.264021 | AR23: 0.369401 | AS23: -0.15021 | AT23: -0.07452
A24: 11.Lack of engineering experience | B24: 0.436309 | C24: 0.427641 | D24: 0.382316 | E24: 0.515672 | F24: 0.497702 | G24: 0.65229 | H24: 0.67464 | I24: 0.610079 | J24: 0.640484 | K24: 0.534699 | L24: 1 | M24: 0.673701 | N24: 0.742574 | O24: 0.15664 | P24: 0.231625 | Q24: 0.39417 | R24: 0.170229 | S24: 0.367693 | T24: 0.292584 | U24: 0.274944 | V24: -0.0177 | W24: 0.109076 | X24: 0.129685 | Y24: 0.366931 | Z24: 0.309221 | AA24: 0.457121 | AB24: 0.50896 | AC24: 0.334607 | AD24: 0.159702 | AE24: 0.073713 | AF24: 0.260559 | AG24: 0.187557 | AH24: 0.442714 | AI24: 0.486403 | AJ24: 0.426793 | AK24: 0.192961 | AL24: 0.017981 | AM24: 0.209146 | AN24: 0.124185 | AO24: 0.466641 | AP24: 0.383385 | AQ24: 0.435719 | AR24: 0.23868 | AS24: -0.10328 | AT24: 0.004912
A25: 12.Construction cost underestimation | B25: 0.308012 | C25: 0.197617 | D25: 0.358718 | E25: 0.360599 | F25: 0.490624 | G25: 0.660151 | H25: 0.594184 | I25: 0.660787 | J25: 0.716775 | K25: 0.592702 | L25: 0.673701 | M25: 1 | N25: 0.708867 | O25: 0.007546 | P25: 0.051844 | Q25: 0.37198 | R25: 0.010037 | S25: 0.439861 | T25: 0.249239 | U25: 0.302513 | V25: 0.224564 | W25: 0.195931 | X25: 0.089976 | Y25: 0.301563 | Z25: 0.385961 | AA25: 0.439367 | AB25: 0.446511 | AC25: 0.331241 | AD25: 0.086707 | AE25: 0.208261 | AF25: 0.304288 | AG25: 0.229953 | AH25: 0.461196 | AI25: 0.434186 | AJ25: 0.411536 | AK25: 0.065903 | AL25: 0.369358 | AM25: 0.420076 | AN25: 0.276308 | AO25: 0.392301 | AP25: 0.404163 | AQ25: 0.433821 | AR25: 0.187331 | AS25: -0.17828 | AT25: -0.03834
... A58: Relevant working experience | B58: -0.15217 | C58: -0.18119 | D58: -0.25457 | E58: -0.15982 | F58: -0.18844 | G58: 0.093833 | H58: -0.02331 | I58: 0.058905 | J58: -0.10373 | K58: -0.07452 | L58: 0.004912 | M58: -0.03834 | N58: 0.025722 | O58: 0.139253 | P58: -0.04215 | Q58: 0.075759 | R58: -0.0008 | S58: -0.02685 | T58: -0.10233 | U58: -0.10469 | V58: -0.10628 | W58: -0.12527 | X58: -0.0794 | Y58: 0.031313 | Z58: -0.05293 | AA58: -0.1027 | AB58: -0.09904 | AC58: -0.04329 | AD58: -0.00079 | AE58: -0.01927 | AF58: -0.03121 | AG58: -0.21396 | AH58: 0.018106 | AI58: 0.025474 | AJ58: -0.06804 | AK58: -0.0748 | AL58: -0.1039 | AM58: -0.12221 | AN58: -0.07477 | AO58: -0.04059 | AP58: -0.07443 | AQ58: -0.22453 | AR58: -0.02073 | AS58: -0.0357 | AT58: 1
B59: 4.246842 | C59: 3.320428 | D59: 2.255776 | E59: 5.220122 | F59: 6.172765 | G59: 6.357509 | H59: 7.491631 | I59: 6.09855 | J59: 6.69014 | K59: 6.1092 | L59: 6.853152 | M59: 6.741862 | N59: 6.359313 | O59: 2.56826 | P59: 3.511436 | Q59: 4.535595 | R59: 2.322142 | S59: 4.550833 | T59: 4.331501 | U59: 4.177802 | V59: 3.059908 | W59: 2.950592 | X59: 0.900143 | Y59: 5.193314 | Z59: 4.760238 | AA59: 6.929866 | AB59: 5.936491 | AC59: 3.2537 | AD59: 2.112584 | AE59: 2.955571 | AF59: 4.561587 | AG59: 2.182358 | AH59: 5.670787 | AI59: 5.345282 | AJ59: 3.381428 | AK59: 2.140692 | AL59: 2.573149 | AM59: 3.212254 | AN59: 2.3284 | AO59: 3.528989 | AP59: 5.028425 | AQ59: 3.41878 | AR59: 3.122772 | AS59: 0.699455 | AT59: 0.470446 | AU59: 185.6321
A61: Inverse of Correlation Matrix
